Workbook

Sheet Dashboard

Sheet Analysis Sheet
A1: Student Performance Analysis
B9: Import the csv file into excel
B11: Data is from: | D11: A to O columns
D12: 2 to 10001 Rows
B16: 1. Check for missing values: | E16: COUNTIF(a2:2100, "")
B18: A | C18: B | D18: =C18 -> B | E18: =D18 -> B
B19: =COUNTIF('Student Performance Dataset'!A$1:A$10001,"") -> 0 | C19: =COUNTIF('Student Performance Dataset'!B$1:B$10001,"") -> 0 | D19: =COUNTIF('Student Performance Dataset'!C$1:C$10001,"") -> 0 | E19: =COUNTIF('Student Performance Dataset'!D$1:D$10001,"") -> 0 | F19: =COUNTIF('Student Performance Dataset'!E$1:E$10001,"") -> 0 | G19: =COUNTIF('Student Performance Dataset'!F$1:F$10001,"") -> 0 | H19: =COUNTIF('Student Performance Dataset'!G$1:G$10001,"") -> 0 | I19: =COUNTIF('Student Performance Dataset'!H$1:H$10001,"") -> 0 | ... P19: =COUNTIF('Student Performance Dataset'!O$1:O$10001,"") -> 0
B21: Another way is to use this: | E21: COUNTBLANK('Student Performance Dataset'!A$1:O$10001)
B22: =COUNTBLANK('Student Performance Dataset'!A$1:O$10001) -> 0
B25: 2. Check for Duplicates:
C26: Data Tab > Remove Duplicates
B29: 3. Covert the types of columns properly.
B32: a. Pivot table : Final grade by gender
C34: Count of Final_Grade | D34: Column Labels
C35: Row Labels | D35: A | E35: B | F35: C | G35: D | H35: Grand Total
C36: Female | D36: 1302 | E36: 1197 | F36: 1161 | G36: 1186 | H36: 4846
C37: Male | D37: 1262 | E37: 1168 | F37: 1168 | G37: 1150 | H37: 4748
C38: Other | D38: 114 | E38: 90 | F38: 111 | G38: 91 | H38: 406
C39: Grand Total | D39: 2678 | E39: 2455 | F39: 2440 | G39: 2427 | H39: 10000
B41: Grade distribution is relatively balanced between male and female
B42: female students have a slight edge in top grades
B43: Consistency Across Grades for Both Genders i.e, students have a fairly even distribution across Grades A to D.
B46: Question: count the number of female students who scored grade 'A'?
C48: =COUNTIFS(Student_Performance_Dataset[Gender],"Female",Student_Performance_Dataset[Final_Grade],"A") -> 1302 | E48: COUNTIFS(Student_Performance_Dataset[Gender],"Female",Student_Performance_Dataset[Final_Grade],"A")
B52: b. Let's Bin the Study Hours and group Grades achieved based on that.
B53: you can achive bins like this: select any number in the column > right click > group > min number max number and by means bin size
B54: =MAX(Student_Performance_Dataset[Study_Hours_per_Week]) -> 49
B60: Count of Final_Grade | C60: Column Labels
B61: Row Labels | C61: A | D61: B | E61: C | F61: D | G61: Grand Total
B62: 4-7 | C62: 165 | D62: 170 | E62: 157 | F62: 151 | G62: 643
B63: 8-11 | C63: 247 | D63: 209 | E63: 200 | F63: 228 | G63: 884
B64: 12-15 | C64: 232 | D64: 224 | E64: 214 | F64: 226 | G64: 896
B65: >20 | C65: 1752 | D65: 1592 | E65: 1564 | F65: 1564 | G65: 6472
B66: 16-20 | C66: 282 | D66: 260 | E66: 305 | F66: 258 | G66: 1105
B67: Grand Total | C67: 2678 | D67: 2455 | E67: 2440 | F67: 2427 | G67: 10000
B71: Highest Performance Correlates with 20+ Study Hours
B72: Minimal Study Time Results in Poorer Performance
B73: Distribution of Top Performers Is Skewed Toward 20+ Group
B74: 6–10, 11–15, and 16–20 Groups Show Moderate Performance
B80: Exam Score by Learning Style
...

Sheet Student Performance Dataset
A1: Student_ID | B1: Age | C1: Gender | D1: Study_Hours_per_Week | E1: Preferred_Learning_Style | F1: Online_Courses_Completed | G1: Participation_in_Discussions | H1: Assignment_Completion_Rate (%) | I1: Exam_Score (%) | J1: Attendance_Rate (%) | K1: Use_of_Educational_Tech | L1: Self_Reported_Stress_Level | M1: Time_Spent_on_Social_Media (hours/week) | N1: Sleep_Hours_per_Night | O1: Final_Grade
A2: S00016 | B2: 25 | C2: Female | D2: 28 | E2: Reading/Writing | F2: 13 | G2: Yes | H2: 85 | I2: 90 | J2: 76 | K2: Yes | L2: Medium | M2: 5 | N2: 8 | O2: A
A3: S00017 | B3: 19 | C3: Male | D3: 11 | E3: Visual | F3: 20 | G3: Yes | H3: 81 | I3: 93 | J3: 93 | K3: No | L3: Medium | M3: 6 | N3: 9 | O3: A
A4: S00018 | B4: 18 | C4: Male | D4: 8 | E4: Kinesthetic | F4: 9 | G4: Yes | H4: 52 | I4: 97 | J4: 69 | K4: No | L4: Low | M4: 1 | N4: 5 | O4: A
A5: S00021 | B5: 19 | C5: Male | D5: 30 | E5: Reading/Writing | F5: 0 | G5: Yes | H5: 89 | I5: 97 | J5: 90 | K5: Yes | L5: Low | M5: 26 | N5: 10 | O5: A
A6: S00024 | B6: 25 | C6: Male | D6: 41 | E6: Reading/Writing | F6: 6 | G6: Yes | H6: 68 | I6: 93 | J6: 100 | K6: No | L6: Medium | M6: 23 | N6: 7 | O6: A
A7: S00029 | B7: 24 | C7: Female | D7: 39 | E7: Kinesthetic | F7: 9 | G7: No | H7: 79 | I7: 90 | J7: 91 | K7: Yes | L7: Medium | M7: 21 | N7: 6 | O7: A
A8: S00034 | B8: 25 | C8: Other | D8: 6 | E8: Visual | F8: 10 | G8: Yes | H8: 96 | I8: 100 | J8: 71 | K8: Yes | L8: Medium | M8: 2 | N8: 7 | O8: A
A9: S00039 | B9: 21 | C9: Female | D9: 20 | E9: Kinesthetic | F9: 1 | G9: Yes | H9: 64 | I9: 99 | J9: 62 | K9: No | L9: High | M9: 2 | N9: 4 | O9: A
A10: S00043 | B10: 25 | C10: Other | D10: 24 | E10: Auditory | F10: 19 | G10: No | H10: 90 | I10: 93 | J10: 54 | K10: Yes | L10: High | M10: 17 | N10: 9 | O10: A
A11: S00046 | B11: 28 | C11: Other | D11: 6 | E11: Visual | F11: 13 | G11: No | H11: 81 | I11: 92 | J11: 90 | K11: No | L11: Medium | M11: 6 | N11: 10 | O11: A
A12: S00052 | B12: 21 | C12: Female | D12: 33 | E12: Visual | F12: 9 | G12: Yes | H12: 99 | I12: 87 | J12: 79 | K12: No | L12: High | M12: 21 | N12: 7 | O12: A
A13: S00055 | B13: 25 | C13: Male | D13: 39 | E13: Reading/Writing | F13: 15 | G13: Yes | H13: 88 | I13: 89 | J13: 63 | K13: No | L13: Medium | M13: 5 | N13: 5 | O13: A
... A10001: S10000 | B10001: 24 | C10001: Male | D10001: 8 | E10001: Visual | F10001: 20 | G10001: Yes | H10001: 87 | I10001: 40 | J10001: 81 | K10001: No | L10001: High | M10001: 17 | N10001: 4 | O10001: D
